Workbook

Sheet hmeq
A1: BAD | B1: MORTDUE | C1: VALUE | D1: JOB | E1: YOJ | F1: DEROG | G1: DELINQ | H1: CLAGE | I1: NINQ | J1: CLNO | K1: DEBTINC
A2: 1 | B2: 25860 | C2: 39025 | D2: Other | E2: 10.5 | F2: 0 | G2: 0 | H2: 94.366667 | I2: 1 | J2: 9
A3: 1 | B3: 70053 | C3: 68400 | D3: Other | E3: 7 | F3: 0 | G3: 2 | H3: 121.83333 | I3: 0 | J3: 14
A4: 1 | B4: 13500 | C4: 16700 | D4: Other | E4: 4 | F4: 0 | G4: 0 | H4: 149.46667 | I4: 1 | J4: 10
A5: 1
A6: 0 | B6: 97800 | C6: 112000 | D6: Office | E6: 3 | F6: 0 | G6: 0 | H6: 93.333333 | I6: 0 | J6: 14
A7: 1 | B7: 30548 | C7: 40320 | D7: Other | E7: 9 | F7: 0 | G7: 0 | H7: 101.466 | I7: 1 | J7: 8 | K7: 37.113614
A8: 1 | B8: 48649 | C8: 57037 | D8: Other | E8: 5 | F8: 3 | G8: 2 | H8: 77.1 | I8: 1 | J8: 17
A9: 1 | B9: 28502 | C9: 43034 | D9: Other | E9: 11 | F9: 0 | G9: 0 | H9: 88.76603 | I9: 0 | J9: 8 | K9: 36.884894
A10: 1 | B10: 32700 | C10: 46740 | D10: Other | E10: 3 | F10: 0 | G10: 2 | H10: 216.93333 | I10: 1 | J10: 12
A11: 1 | C11: 62250 | D11: Sales | E11: 16 | F11: 0 | G11: 0 | H11: 115.8 | I11: 0 | J11: 13
A12: 1 | B12: 22608 | E12: 18
A13: 1 | B13: 20627 | C13: 29800 | D13: Office | E13: 11 | F13: 0 | G13: 1 | H13: 122.53333 | I13: 1 | J13: 9
A14: 1 | B14: 45000 | C14: 55000 | D14: Other | E14: 3 | F14: 0 | G14: 0 | H14: 86.066667 | I14: 2 | J14: 25
A15: 0 | B15: 64536 | C15: 87400 | D15: Mgr | E15: 2.5 | F15: 0 | G15: 0 | H15: 147.13333 | I15: 0 | J15: 24
A16: 1 | B16: 71000 | C16: 83850 | D16: Other | E16: 8 | F16: 0 | G16: 1 | H16: 123 | I16: 0 | J16: 16
A17: 1 | B17: 24280 | C17: 34687 | D17: Other | F17: 0 | G17: 1 | H17: 300.86667 | I17: 0 | J17: 8
A18: 1 | B18: 90957 | C18: 102600 | D18: Mgr | E18: 7 | F18: 2 | G18: 6 | H18: 122.9 | I18: 1 | J18: 22
A19: 1 | B19: 23030 | E19: 19 | K19: 3.7113123
A20: 1 | B20: 28192 | C20: 40150 | D20: Other | E20: 4.5 | F20: 0 | G20: 0 | H20: 54.6 | I20: 1 | J20: 16
A21: 0 | B21: 102370 | C21: 120953 | D21: Office | E21: 2 | F21: 0 | G21: 0 | H21: 90.992533 | I21: 0 | J21: 13 | K21: 31.588503
A22: 1 | B22: 37626 | C22: 46200 | D22: Other | E22: 3 | F22: 0 | G22: 1 | H22: 122.26667 | I22: 1 | J22: 14
A23: 1 | B23: 50000 | C23: 73395 | D23: ProfExe | E23: 5 | F23: 1 | G23: 0 | I23: 1 | J23: 0
A24: 1 | B24: 28000 | C24: 40800 | D24: Mgr | E24: 12 | F24: 0 | G24: 0 | H24: 67.2 | I24: 2 | J24: 22
A25: 1 | B25: 18000 | D25: Mgr | E25: 22 | G25: 2 | H25: 121.73333 | I25: 0 | J25: 10
A26: 1 | C26: 17180 | D26: Other | F26: 0 | G26: 0 | H26: 14.566667 | I26: 3 | J26: 4
A27: 1 | B27: 34863 | C27: 47471 | D27: Mgr | E27: 12 | F27: 0 | G27: 0 | H27: 70.49108 | I27: 1 | J27: 21 | K27: 38.263601
A28: 0 | B28: 98449 | C28: 117195 | D28: Office | E28: 4 | F28: 0 | G28: 0 | H28: 93.811775 | I28: 0 | J28: 13 | K28: 29.681827
A29: 1 | B29: 15000 | C29: 20200 | E29: 18 | F29: 0 | G29: 0 | H29: 136.06667 | I29: 1 | J29: 19
A30: 1 | B30: 25116 | C30: 36350 | D30: Other | E30: 10 | F30: 1 | G30: 2 | H30: 276.96667 | I30: 0 | J30: 9
A31: 0 | B31: 7229 | C31: 44516 | D31: Self | F31: 0 | G31: 0 | H31: 208 | I31: 0 | J31: 12
A32: 0 | B32: 71408 | C32: 78600 | D32: ProfExe | E32: 8 | F32: 0 | G32: 0 | H32: 255.73333 | I32: 0 | J32: 12
A33: 1 | B33: 50795 | C33: 63100 | D33: Self | E33: 26 | F33: 2 | G33: 15 | H33: 145.63333 | I33: 3 | J33: 45
A34: 1 | B34: 4000 | C34: 60850 | D34: Other | E34: 16 | F34: 4 | G34: 0 | H34: 112.63333 | I34: 2 | J34: 9
A35: 1 | B35: 78600 | C35: 113000 | D35: ProfExe | E35: 6 | F35: 1 | G35: 0 | H35: 165.33333 | I35: 2 | J35: 26
A36: 0 | B36: 103949 | C36: 112505 | D36: Office | E36: 1 | F36: 0 | G36: 0 | H36: 96.10233 | I36: 0 | J36: 13 | K36: 30.051136
A37: 0 | B37: 104373 | C37: 120702 | D37: Office | E37: 2 | F37: 0 | G37: 0 | H37: 101.5403 | I37: 0 | J37: 13 | K37: 29.915859
A38: 1 | B38: 7750 | C38: 67996 | D38: Other | E38: 16 | F38: 3 | G38: 0 | H38: 122.20466 | I38: 2 | J38: 8 | K38: 36.211348
A39: 1 | B39: 61962 | C39: 70915 | D39: Mgr | E39: 2 | F39: 0 | G39: 0 | H39: 282.80166 | I39: 3 | J39: 37 | K39: 49.206396
A40: 0 | B40: 104570 | C40: 121729 | D40: Office | E40: 2 | F40: 0 | G40: 0 | H40: 85.884372 | I40: 0 | J40: 14 | K40: 32.059783
...

Sheet Data
B1: Total loans | C1: Defaults | D1: Defaults rate
B2: =COUNT(A11:A5970) -> 5960 | C2: =SUM(A11:A5970) -> 1189 | D2: =C2/B2 -> 0.19949664 | L2: Total Exposure EAD | M2: Total RWA | N2: Total Capital Requirement | V2: Total RWA_IRB | W2: Total Capital_IRB
L3: =SUM(Table2[EAD]) -> 4.0140637e+08 | M3: =SUM(Table2[RWA STD]) -> 1.412735e+08 | N3: =SUM(Table2[Capital STD]) -> 11301880 | O3: =M3*0.08 -> 11301880 | V3: =SUM(Table2[RWA_IRB]) -> 718416553 | W3: =SUM(Table2[Capital_IRB]) -> 57473324
A10: BAD | B10: MORTDUE | C10: VALUE | D10: JOB | E10: YOJ | F10: DEROG | G10: DELINQ | H10: CLAGE | I10: NINQ | J10: CLNO | K10: DEBTINC | L10: EAD | M10: Adjusted Value | N10: LTV | O10: Risk Weight | P10: RWA STD | Q10: Capital STD | R10: PD_model | S10: LGD | T10: EAD_IRB | U10: K | V10: RWA_IRB | W10: Capital_IRB
A11: 1 | B11: 25860 | C11: 39025 | D11: Other | E11: 10.5 | F11: 0 | G11: 0 | H11: 94.366667 | I11: 1 | J11: 9 | L11: =$B11 -> 25860 | M11: =IF($C11="", $B11/0.45, $C11) -> 39025 | N11: =IF(M11=0,"",L11/M11) -> 0.66265215 | O11: =IF(N11<=0.5,0.2, IF(N11<=0.6,0.25, IF(N11<=0.8,0.3, IF(N11<=0.9,0.45, IF(N11<=1,0.7,1.05))))) -> 0.3 | P11: =$L11*O11 -> 7758 | Q11: =$P11*0.08 -> 620.64 | R11: 0.21890293 | S11: 0.4 | T11: 25860 | U11: 0.18284302 | V11: 59104.006 | W11: 4728.3204
A12: 1 | B12: 70053 | C12: 68400 | D12: Other | E12: 7 | F12: 0 | G12: 2 | H12: 121.83333 | I12: 0 | J12: 14 | L12: =$B12 -> 70053 | M12: =IF($C12="", $B12/0.45, $C12) -> 68400 | N12: =IF(M12=0,"",L12/M12) -> 1.0241667 | O12: =IF(N12<=0.5,0.2, IF(N12<=0.6,0.25, IF(N12<=0.8,0.3, IF(N12<=0.9,0.45, IF(N12<=1,0.7,1.05))))) -> 1.05 | P12: =$L12*O12 -> 73555.65 | Q12: =$P12*0.08 -> 5884.452 | R12: 0.47965467 | S12: 0.4 | T12: 70053 | U12: 0.16535115 | V12: 144791.8 | W12: 11583.344
A13: 1 | B13: 13500 | C13: 16700 | D13: Other | E13: 4 | F13: 0 | G13: 0 | H13: 149.46667 | I13: 1 | J13: 10 | L13: =$B13 -> 13500 | M13: =IF($C13="", $B13/0.45, $C13) -> 16700 | N13: =IF(M13=0,"",L13/M13) -> 0.80838323 | O13: =IF(N13<=0.5,0.2, IF(N13<=0.6,0.25, IF(N13<=0.8,0.3, IF(N13<=0.9,0.45, IF(N13<=1,0.7,1.05))))) -> 0.45 | P13: =$L13*O13 -> 6075 | Q13: =$P13*0.08 -> 486 | R13: 0.17134244 | S13: 0.4 | T13: 13500 | U13: 0.17387082 | V13: 29340.7 | W13: 2347.256
A14: 1 | L14: =$B14 | M14: =IF($C14="", $B14/0.45, $C14) -> 0 | N14: =IF(M14=0,"",L14/M14) | O14: =IF(N14<=0.5,0.2, IF(N14<=0.6,0.25, IF(N14<=0.8,0.3, IF(N14<=0.9,0.45, IF(N14<=1,0.7,1.05))))) -> 1.05 | P14: =$L14*O14 -> 0 | Q14: =$P14*0.08 -> 0 | R14: 0.12287614 | S14: 0.4 | T14: 0 | U14: 0.15709862 | V14: 0 | W14: 0
A15: 0 | B15: 97800 | C15: 112000 | D15: Office | E15: 3 | F15: 0 | G15: 0 | H15: 93.333333 | I15: 0 | J15: 14 | L15: =$B15 -> 97800 | M15: =IF($C15="", $B15/0.45, $C15) -> 112000 | N15: =IF(M15=0,"",L15/M15) -> 0.87321429 | O15: =IF(N15<=0.5,0.2, IF(N15<=0.6,0.25, IF(N15<=0.8,0.3, IF(N15<=0.9,0.45, IF(N15<=1,0.7,1.05))))) -> 0.45 | P15: =$L15*O15 -> 44010 | Q15: =$P15*0.08 -> 3520.8 | R15: 0.10125919 | S15: 0.4 | T15: 97800 | U15: 0.14608634 | V15: 178590.55 | W15: 14287.244
A16: 1 | B16: 30548 | C16: 40320 | D16: Other | E16: 9 | F16: 0 | G16: 0 | H16: 101.466 | I16: 1 | J16: 8 | K16: 37.113614 | L16: =$B16 -> 30548 | M16: =IF($C16="", $B16/0.45, $C16) -> 40320 | N16: =IF(M16=0,"",L16/M16) -> 0.75763889 | O16: =IF(N16<=0.5,0.2, IF(N16<=0.6,0.25, IF(N16<=0.8,0.3, IF(N16<=0.9,0.45, IF(N16<=1,0.7,1.05))))) -> 0.3 | P16: =$L16*O16 -> 9164.4 | Q16: =$P16*0.08 -> 733.152 | R16: 0.24463827 | S16: 0.4 | T16: 30548 | U16: 0.18542878 | V16: 70805.979 | W16: 5664.4783
A17: 1 | B17: 48649 | C17: 57037 | D17: Other | E17: 5 | F17: 3 | G17: 2 | H17: 77.1 | I17: 1 | J17: 17 | L17: =$B17 -> 48649 | M17: =IF($C17="", $B17/0.45, $C17) -> 57037 | N17: =IF(M17=0,"",L17/M17) -> 0.85293757 | O17: =IF(N17<=0.5,0.2, IF(N17<=0.6,0.25, IF(N17<=0.8,0.3, IF(N17<=0.9,0.45, IF(N17<=1,0.7,1.05))))) -> 0.45 | P17: =$L17*O17 -> 21892.05 | Q17: =$P17*0.08 -> 1751.364 | R17: 0.88293551 | S17: 0.4 | T17: 48649 | U17: 0.044898823 | V17: 27303.536 | W17: 2184.2829
A18: 1 | B18: 28502 | C18: 43034 | D18: Other | E18: 11 | F18: 0 | G18: 0 | H18: 88.76603 | I18: 0 | J18: 8 | K18: 36.884894 | L18: =$B18 -> 28502 | M18: =IF($C18="", $B18/0.45, $C18) -> 43034 | N18: =IF(M18=0,"",L18/M18) -> 0.66231352 | O18: =IF(N18<=0.5,0.2, IF(N18<=0.6,0.25, IF(N18<=0.8,0.3, IF(N18<=0.9,0.45, IF(N18<=1,0.7,1.05))))) -> 0.3 | P18: =$L18*O18 -> 8550.6 | Q18: =$P18*0.08 -> 684.048 | R18: 0.22896573 | S18: 0.4 | T18: 28502 | U18: 0.18402054 | V18: 65561.918 | W18: 5244.9534
A19: 1 | B19: 32700 | C19: 46740 | D19: Other | E19: 3 | F19: 0 | G19: 2 | H19: 216.93333 | I19: 1 | J19: 12 | L19: =$B19 -> 32700 | M19: =IF($C19="", $B19/0.45, $C19) -> 46740 | N19: =IF(M19=0,"",L19/M19) -> 0.69961489 | O19: =IF(N19<=0.5,0.2, IF(N19<=0.6,0.25, IF(N19<=0.8,0.3, IF(N19<=0.9,0.45, IF(N19<=1,0.7,1.05))))) -> 0.3 | P19: =$L19*O19 -> 9810 | Q19: =$P19*0.08 -> 784.8 | R19: 0.39224973 | S19: 0.4 | T19: 32700 | U19: 0.17978772 | V19: 73488.229 | W19: 5879.0583
A20: 1 | C20: 62250 | D20: Sales | E20: 16 | F20: 0 | G20: 0 | H20: 115.8 | I20: 0 | J20: 13 | L20: =$B20 | M20: =IF($C20="", $B20/0.45, $C20) -> 62250 | N20: =IF(M20=0,"",L20/M20) -> 0 | O20: =IF(N20<=0.5,0.2, IF(N20<=0.6,0.25, IF(N20<=0.8,0.3, IF(N20<=0.9,0.45, IF(N20<=1,0.7,1.05))))) -> 0.2 | P20: =$L20*O20 -> 0 | Q20: =$P20*0.08 -> 0 | R20: 0.36092997 | S20: 0.4 | T20: 0 | U20: 0.18327943 | V20: 0 | W20: 0
A21: 1 | B21: 22608 | E21: 18 | L21: =$B21 -> 22608 | M21: =IF($C21="", $B21/0.45, $C21) -> 50240 | N21: =IF(M21=0,"",L21/M21) -> 0.45 | O21: =IF(N21<=0.5,0.2, IF(N21<=0.6,0.25, IF(N21<=0.8,0.3, IF(N21<=0.9,0.45, IF(N21<=1,0.7,1.05))))) -> 0.2 | P21: =$L21*O21 -> 4521.6 | Q21: =$P21*0.08 -> 361.728 | R21: 0.1149779 | S21: 0.4 | T21: 22608 | U21: 0.15338039 | V21: 43345.297 | W21: 3467.6238
A22: 1 | B22: 20627 | C22: 29800 | D22: Office | E22: 11 | F22: 0 | G22: 1 | H22: 122.53333 | I22: 1 | J22: 9 | L22: =$B22 -> 20627 | M22: =IF($C22="", $B22/0.45, $C22) -> 29800 | N22: =IF(M22=0,"",L22/M22) -> 0.69218121 | O22: =IF(N22<=0.5,0.2, IF(N22<=0.6,0.25, IF(N22<=0.8,0.3, IF(N22<=0.9,0.45, IF(N22<=1,0.7,1.05))))) -> 0.3 | P22: =$L22*O22 -> 6188.1 | Q22: =$P22*0.08 -> 495.048 | R22: 0.20170398 | S22: 0.4 | T22: 20627 | U22: 0.1802884 | V22: 46485.11 | W22: 3718.8088
A23: 1 | B23: 45000 | C23: 55000 | D23: Other | E23: 3 | F23: 0 | G23: 0 | H23: 86.066667 | I23: 2 | J23: 25 | L23: =$B23 -> 45000 | M23: =IF($C23="", $B23/0.45, $C23) -> 55000 | N23: =IF(M23=0,"",L23/M23) -> 0.81818182 | O23: =IF(N23<=0.5,0.2, IF(N23<=0.6,0.25, IF(N23<=0.8,0.3, IF(N23<=0.9,0.45, IF(N23<=1,0.7,1.05))))) -> 0.45 | P23: =$L23*O23 -> 20250 | Q23: =$P23*0.08 -> 1620 | R23: 0.19691079 | S23: 0.4 | T23: 45000 | U23: 0.17944561 | V23: 100938.16 | W23: 8075.0526
A24: 0 | B24: 64536 | C24: 87400 | D24: Mgr | E24: 2.5 | F24: 0 | G24: 0 | H24: 147.13333 | I24: 0 | J24: 24 | L24: =$B24 -> 64536 | M24: =IF($C24="", $B24/0.45, $C24) -> 87400 | N24: =IF(M24=0,"",L24/M24) -> 0.73839817 | O24: =IF(N24<=0.5,0.2, IF(N24<=0.6,0.25, IF(N24<=0.8,0.3, IF(N24<=0.9,0.45, IF(N24<=1,0.7,1.05))))) -> 0.3 | P24: =$L24*O24 -> 19360.8 | Q24: =$P24*0.08 -> 1548.864 | R24: 0.11442786 | S24: 0.4 | T24: 64536 | U24: 0.15310902 | V24: 123513.05 | W24: 9881.0437
A25: 1 | B25: 71000 | C25: 83850 | D25: Other | E25: 8 | F25: 0 | G25: 1 | H25: 123 | I25: 0 | J25: 16 | L25: =$B25 -> 71000 | M25: =IF($C25="", $B25/0.45, $C25) -> 83850 | N25: =IF(M25=0,"",L25/M25) -> 0.84675015 | O25: =IF(N25<=0.5,0.2, IF(N25<=0.6,0.25, IF(N25<=0.8,0.3, IF(N25<=0.9,0.45, IF(N25<=1,0.7,1.05))))) -> 0.45 | P25: =$L25*O25 -> 31950 | Q25: =$P25*0.08 -> 2556 | R25: 0.28312035 | S25: 0.4 | T25: 71000 | U25: 0.18694426 | V25: 165913.03 | W25: 13273.043
A26: 1 | B26: 24280 | C26: 34687 | D26: Other | F26: 0 | G26: 1 | H26: 300.86667 | I26: 0 | J26: 8 | L26: =$B26 -> 24280 | M26: =IF($C26="", $B26/0.45, $C26) -> 34687 | N26: =IF(M26=0,"",L26/M26) -> 0.69997405 | O26: =IF(N26<=0.5,0.2, IF(N26<=0.6,0.25, IF(N26<=0.8,0.3, IF(N26<=0.9,0.45, IF(N26<=1,0.7,1.05))))) -> 0.3 | P26: =$L26*O26 -> 7284 | Q26: =$P26*0.08 -> 582.72 | R26: 0.14303485 | S26: 0.4 | T26: 24280 | U26: 0.16522286 | V26: 50145.138 | W26: 4011.611
A27: 1 | B27: 90957 | C27: 102600 | D27: Mgr | E27: 7 | F27: 2 | G27: 6 | H27: 122.9 | I27: 1 | J27: 22 | L27: =$B27 -> 90957 | M27: =IF($C27="", $B27/0.45, $C27) -> 102600 | N27: =IF(M27=0,"",L27/M27) -> 0.88652047 | O27: =IF(N27<=0.5,0.2, IF(N27<=0.6,0.25, IF(N27<=0.8,0.3, IF(N27<=0.9,0.45, IF(N27<=1,0.7,1.05))))) -> 0.45 | P27: =$L27*O27 -> 40930.65 | Q27: =$P27*0.08 -> 3274.452 | R27: 0.98441901 | S27: 0.4 | T27: 90957 | U27: 0.0061769245 | V27: 7022.9315 | W27: 561.83452
A28: 1 | B28: 23030 | E28: 19 | K28: 3.7113123 | L28: =$B28 -> 23030 | M28: =IF($C28="", $B28/0.45, $C28) -> 51177.778 | N28: =IF(M28=0,"",L28/M28) -> 0.45 | O28: =IF(N28<=0.5,0.2, IF(N28<=0.6,0.25, IF(N28<=0.8,0.3, IF(N28<=0.9,0.45, IF(N28<=1,0.7,1.05))))) -> 0.2 | P28: =$L28*O28 -> 4606 | Q28: =$P28*0.08 -> 368.48 | R28: 0.015126635 | S28: 0.4 | T28: 23030 | U28: 0.052507201 | V28: 15115.511 | W28: 1209.2408
A29: 1 | B29: 28192 | C29: 40150 | D29: Other | E29: 4.5 | F29: 0 | G29: 0 | H29: 54.6 | I29: 1 | J29: 16 | L29: =$B29 -> 28192 | M29: =IF($C29="", $B29/0.45, $C29) -> 40150 | N29: =IF(M29=0,"",L29/M29) -> 0.70216687 | O29: =IF(N29<=0.5,0.2, IF(N29<=0.6,0.25, IF(N29<=0.8,0.3, IF(N29<=0.9,0.45, IF(N29<=1,0.7,1.05))))) -> 0.3 | P29: =$L29*O29 -> 8457.6 | Q29: =$P29*0.08 -> 676.608 | R29: 0.23934793 | S29: 0.4 | T29: 28192 | U29: 0.18500901 | V29: 65197.174 | W29: 5215.7739
A30: 0 | B30: 102370 | C30: 120953 | D30: Office | E30: 2 | F30: 0 | G30: 0 | H30: 90.992533 | I30: 0 | J30: 13 | K30: 31.588503 | L30: =$B30 -> 102370 | M30: =IF($C30="", $B30/0.45, $C30) -> 120953 | N30: =IF(M30=0,"",L30/M30) -> 0.84636181 | O30: =IF(N30<=0.5,0.2, IF(N30<=0.6,0.25, IF(N30<=0.8,0.3, IF(N30<=0.9,0.45, IF(N30<=1,0.7,1.05))))) -> 0.45 | P30: =$L30*O30 -> 46066.5 | Q30: =$P30*0.08 -> 3685.32 | R30: 0.085982386 | S30: 0.4 | T30: 102370 | U30: 0.13650567 | V30: 174676.06 | W30: 13974.085
A31: 1 | B31: 37626 | C31: 46200 | D31: Other | E31: 3 | F31: 0 | G31: 1 | H31: 122.26667 | I31: 1 | J31: 14 | L31: =$B31 -> 37626 | M31: =IF($C31="", $B31/0.45, $C31) -> 46200 | N31: =IF(M31=0,"",L31/M31) -> 0.81441558 | O31: =IF(N31<=0.5,0.2, IF(N31<=0.6,0.25, IF(N31<=0.8,0.3, IF(N31<=0.9,0.45, IF(N31<=1,0.7,1.05))))) -> 0.45 | P31: =$L31*O31 -> 16931.7 | Q31: =$P31*0.08 -> 1354.536 | R31: 0.3291311 | S31: 0.4 | T31: 37626 | U31: 0.18572187 | V31: 87349.637 | W31: 6987.971
A32: 1 | B32: 50000 | C32: 73395 | D32: ProfExe | E32: 5 | F32: 1 | G32: 0 | I32: 1 | J32: 0 | L32: =$B32 -> 50000 | M32: =IF($C32="", $B32/0.45, $C32) -> 73395 | N32: =IF(M32=0,"",L32/M32) -> 0.68124532 | O32: =IF(N32<=0.5,0.2, IF(N32<=0.6,0.25, IF(N32<=0.8,0.3, IF(N32<=0.9,0.45, IF(N32<=1,0.7,1.05))))) -> 0.3 | P32: =$L32*O32 -> 15000 | Q32: =$P32*0.08 -> 1200 | R32: 0.28630072 | S32: 0.4 | T32: 50000 | U32: 0.18695852 | V32: 116849.08 | W32: 9347.9262
A33: 1 | B33: 28000 | C33: 40800 | D33: Mgr | E33: 12 | F33: 0 | G33: 0 | H33: 67.2 | I33: 2 | J33: 22 | L33: =$B33 -> 28000 | M33: =IF($C33="", $B33/0.45, $C33) -> 40800 | N33: =IF(M33=0,"",L33/M33) -> 0.68627451 | O33: =IF(N33<=0.5,0.2, IF(N33<=0.6,0.25, IF(N33<=0.8,0.3, IF(N33<=0.9,0.45, IF(N33<=1,0.7,1.05))))) -> 0.3 | P33: =$L33*O33 -> 8400 | Q33: =$P33*0.08 -> 672 | R33: 0.20947359 | S33: 0.4 | T33: 28000 | U33: 0.1815308 | V33: 63535.781 | W33: 5082.8625
A34: 1 | B34: 18000 | D34: Mgr | E34: 22 | G34: 2 | H34: 121.73333 | I34: 0 | J34: 10 | L34: =$B34 -> 18000 | M34: =IF($C34="", $B34/0.45, $C34) -> 40000 | N34: =IF(M34=0,"",L34/M34) -> 0.45 | O34: =IF(N34<=0.5,0.2, IF(N34<=0.6,0.25, IF(N34<=0.8,0.3, IF(N34<=0.9,0.45, IF(N34<=1,0.7,1.05))))) -> 0.2 | P34: =$L34*O34 -> 3600 | Q34: =$P34*0.08 -> 288 | R34: 0.4668079 | S34: 0.4 | T34: 18000 | U34: 0.16785273 | V34: 37766.865 | W34: 3021.3492
A35: 1 | C35: 17180 | D35: Other | F35: 0 | G35: 0 | H35: 14.566667 | I35: 3 | J35: 4 | L35: =$B35 | M35: =IF($C35="", $B35/0.45, $C35) -> 17180 | N35: =IF(M35=0,"",L35/M35) -> 0 | O35: =IF(N35<=0.5,0.2, IF(N35<=0.6,0.25, IF(N35<=0.8,0.3, IF(N35<=0.9,0.45, IF(N35<=1,0.7,1.05))))) -> 0.2 | P35: =$L35*O35 -> 0 | Q35: =$P35*0.08 -> 0 | R35: 0.40207598 | S35: 0.4 | T35: 0 | U35: 0.17849135 | V35: 0 | W35: 0
A36: 1 | B36: 34863 | C36: 47471 | D36: Mgr | E36: 12 | F36: 0 | G36: 0 | H36: 70.49108 | I36: 1 | J36: 21 | K36: 38.263601 | L36: =$B36 -> 34863 | M36: =IF($C36="", $B36/0.45, $C36) -> 47471 | N36: =IF(M36=0,"",L36/M36) -> 0.73440627 | O36: =IF(N36<=0.5,0.2, IF(N36<=0.6,0.25, IF(N36<=0.8,0.3, IF(N36<=0.9,0.45, IF(N36<=1,0.7,1.05))))) -> 0.3 | P36: =$L36*O36 -> 10458.9 | Q36: =$P36*0.08 -> 836.712 | R36: 0.22703245 | S36: 0.4 | T36: 34863 | U36: 0.18381151 | V36: 80102.757 | W36: 6408.2205
A37: 0 | B37: 98449 | C37: 117195 | D37: Office | E37: 4 | F37: 0 | G37: 0 | H37: 93.811775 | I37: 0 | J37: 13 | K37: 29.681827 | L37: =$B37 -> 98449 | M37: =IF($C37="", $B37/0.45, $C37) -> 117195 | N37: =IF(M37=0,"",L37/M37) -> 0.84004437 | O37: =IF(N37<=0.5,0.2, IF(N37<=0.6,0.25, IF(N37<=0.8,0.3, IF(N37<=0.9,0.45, IF(N37<=1,0.7,1.05))))) -> 0.45 | P37: =$L37*O37 -> 44302.05 | Q37: =$P37*0.08 -> 3544.164 | R37: 0.074170077 | S37: 0.4 | T37: 98449 | U37: 0.12782248 | V37: 157299.94 | W37: 12583.995
A38: 1 | B38: 15000 | C38: 20200 | E38: 18 | F38: 0 | G38: 0 | H38: 136.06667 | I38: 1 | J38: 19 | L38: =$B38 -> 15000 | M38: =IF($C38="", $B38/0.45, $C38) -> 20200 | N38: =IF(M38=0,"",L38/M38) -> 0.74257426 | O38: =IF(N38<=0.5,0.2, IF(N38<=0.6,0.25, IF(N38<=0.8,0.3, IF(N38<=0.9,0.45, IF(N38<=1,0.7,1.05))))) -> 0.3 | P38: =$L38*O38 -> 4500 | Q38: =$P38*0.08 -> 360 | R38: 0.14195941 | S38: 0.4 | T38: 15000 | U38: 0.16483457 | V38: 30906.482 | W38: 2472.5186
A39: 1 | B39: 25116 | C39: 36350 | D39: Other | E39: 10 | F39: 1 | G39: 2 | H39: 276.96667 | I39: 0 | J39: 9 | L39: =$B39 -> 25116 | M39: =IF($C39="", $B39/0.45, $C39) -> 36350 | N39: =IF(M39=0,"",L39/M39) -> 0.69094911 | O39: =IF(N39<=0.5,0.2, IF(N39<=0.6,0.25, IF(N39<=0.8,0.3, IF(N39<=0.9,0.45, IF(N39<=1,0.7,1.05))))) -> 0.3 | P39: =$L39*O39 -> 7534.8 | Q39: =$P39*0.08 -> 602.784 | R39: 0.42121596 | S39: 0.4 | T39: 25116 | U39: 0.17571162 | V39: 55164.662 | W39: 4413.173
A40: 0 | B40: 7229 | C40: 44516 | D40: Self | F40: 0 | G40: 0 | H40: 208 | I40: 0 | J40: 12 | L40: =$B40 -> 7229 | M40: =IF($C40="", $B40/0.45, $C40) -> 44516 | N40: =IF(M40=0,"",L40/M40) -> 0.16239105 | O40: =IF(N40<=0.5,0.2, IF(N40<=0.6,0.25, IF(N40<=0.8,0.3, IF(N40<=0.9,0.45, IF(N40<=1,0.7,1.05))))) -> 0.2 | P40: =$L40*O40 -> 1445.8 | Q40: =$P40*0.08 -> 115.664 | R40: 0.17670432 | S40: 0.4 | T40: 7229 | U40: 0.1752001 | V40: 15831.519 | W40: 1266.5216
A41: 0 | B41: 71408 | C41: 78600 | D41: ProfExe | E41: 8 | F41: 0 | G41: 0 | H41: 255.73333 | I41: 0 | J41: 12 | L41: =$B41 -> 71408 | M41: =IF($C41="", $B41/0.45, $C41) -> 78600 | N41: =IF(M41=0,"",L41/M41) -> 0.90849873 | O41: =IF(N41<=0.5,0.2, IF(N41<=0.6,0.25, IF(N41<=0.8,0.3, IF(N41<=0.9,0.45, IF(N41<=1,0.7,1.05))))) -> 0.7 | P41: =$L41*O41 -> 49985.6 | Q41: =$P41*0.08 -> 3998.848 | R41: 0.081912023 | S41: 0.4 | T41: 71408 | U41: 0.13365174 | V41: 119297.54 | W41: 9543.8035
A42: 1 | B42: 50795 | C42: 63100 | D42: Self | E42: 26 | F42: 2 | G42: 15 | H42: 145.63333 | I42: 3 | J42: 45 | L42: =$B42 -> 50795 | M42: =IF($C42="", $B42/0.45, $C42) -> 63100 | N42: =IF(M42=0,"",L42/M42) -> 0.80499208 | O42: =IF(N42<=0.5,0.2, IF(N42<=0.6,0.25, IF(N42<=0.8,0.3, IF(N42<=0.9,0.45, IF(N42<=1,0.7,1.05))))) -> 0.45 | P42: =$L42*O42 -> 22857.75 | Q42: =$P42*0.08 -> 1828.62 | R42: 0.99998805 | S42: 0.4 | T42: 50795 | U42: 4.7790197e-06 | V42: 3.0343788 | W42: 0.24275031
A43: 1 | B43: 4000 | C43: 60850 | D43: Other | E43: 16 | F43: 4 | G43: 0 | H43: 112.63333 | I43: 2 | J43: 9 | L43: =$B43 -> 4000 | M43: =IF($C43="", $B43/0.45, $C43) -> 60850 | N43: =IF(M43=0,"",L43/M43) -> 0.065735415 | O43: =IF(N43<=0.5,0.2, IF(N43<=0.6,0.25, IF(N43<=0.8,0.3, IF(N43<=0.9,0.45, IF(N43<=1,0.7,1.05))))) -> 0.2 | P43: =$L43*O43 -> 800 | Q43: =$P43*0.08 -> 64 | R43: 0.74297413 | S43: 0.4 | T43: 4000 | U43: 0.093837778 | V43: 4691.8889 | W43: 375.35111
A44: 1 | B44: 78600 | C44: 113000 | D44: ProfExe | E44: 6 | F44: 1 | G44: 0 | H44: 165.33333 | I44: 2 | J44: 26 | L44: =$B44 -> 78600 | M44: =IF($C44="", $B44/0.45, $C44) -> 113000 | N44: =IF(M44=0,"",L44/M44) -> 0.69557522 | O44: =IF(N44<=0.5,0.2, IF(N44<=0.6,0.25, IF(N44<=0.8,0.3, IF(N44<=0.9,0.45, IF(N44<=1,0.7,1.05))))) -> 0.3 | P44: =$L44*O44 -> 23580 | Q44: =$P44*0.08 -> 1886.4 | R44: 0.20789288 | S44: 0.4 | T44: 78600 | U44: 0.18129013 | V44: 178117.55 | W44: 14249.404
A45: 0 | B45: 103949 | C45: 112505 | D45: Office | E45: 1 | F45: 0 | G45: 0 | H45: 96.10233 | I45: 0 | J45: 13 | K45: 30.051136 | L45: =$B45 -> 103949 | M45: =IF($C45="", $B45/0.45, $C45) -> 112505 | N45: =IF(M45=0,"",L45/M45) -> 0.92395005 | O45: =IF(N45<=0.5,0.2, IF(N45<=0.6,0.25, IF(N45<=0.8,0.3, IF(N45<=0.9,0.45, IF(N45<=1,0.7,1.05))))) -> 0.7 | P45: =$L45*O45 -> 72764.3 | Q45: =$P45*0.08 -> 5821.144 | R45: 0.076415411 | S45: 0.4 | T45: 103949 | U45: 0.12957008 | V45: 168358.5 | W45: 13468.68
A46: 0 | B46: 104373 | C46: 120702 | D46: Office | E46: 2 | F46: 0 | G46: 0 | H46: 101.5403 | I46: 0 | J46: 13 | K46: 29.915859 | L46: =$B46 -> 104373 | M46: =IF($C46="", $B46/0.45, $C46) -> 120702 | N46: =IF(M46=0,"",L46/M46) -> 0.86471641 | O46: =IF(N46<=0.5,0.2, IF(N46<=0.6,0.25, IF(N46<=0.8,0.3, IF(N46<=0.9,0.45, IF(N46<=1,0.7,1.05))))) -> 0.45 | P46: =$L46*O46 -> 46967.85 | Q46: =$P46*0.08 -> 3757.428 | R46: 0.073079544 | S46: 0.4 | T46: 104373 | U46: 0.12695604 | V46: 165634.78 | W46: 13250.782
...

Sheet Overwiev
A1: Metric | B1: Value
A2: Total Loans | B2: =Data!B2 -> 5960
A3: Default Rate | B3: =Data!D2 -> 0.19949664
A4: Total Exposure (EAD) | B4: =Data!L3 -> 4.0140637e+08
A5: Total RWA – Standardized | B5: =Data!M3 -> 1.412735e+08
A6: Capital – Standardized | B6: =Data!N3 -> 11301880
A7: Total RWA – IRB | B7: =Data!V3 -> 718416553
A8: Capital – IRB | B8: =Data!W3 -> 57473324
A15: LTV bucket | B15: Count
A16: 0-50% | B16: =COUNTIFS(Data!N11:N5970,">=0",Data!N11:N5970,"<=0.5") -> 1235
A17: 50-70% | B17: =COUNTIFS(Data!N12:N5971,">=0.5",Data!N12:N5971,"<=0.7") -> 1723
A18: 70-90% | B18: =COUNTIFS(Data!N13:N5972,">=0.7",Data!N13:N5972,"<=0.9") -> 2758
A19: 90-100% | B19: =COUNTIFS(Data!N14:N5973,">=0.9",Data!N14:N5973,"<=1") -> 173
A47: Conclusion:
A48: In this portfolio, the IRB approach produces substantially higher capital requirements than the standardized approach. This is driven by the high observed default rate and the high borrower-level PDs estimated by the logistic regression model.
